<?xml version="1.0" encoding="utf-8"?>
<!-- This URDF was automatically created by SolidWorks to URDF Exporter! Originally created by Stephen Brawner (brawner@gmail.com) 
     Commit Version: 1.5.1-0-g916b5db  Build Version: 1.5.7152.31018
     For more information, please see http://wiki.ros.org/sw_urdf_exporter -->
<!--robot
  name="Seguidor_linea_robot"-->
<robot xmlns:xacro="http://www.ros.org/wiki/xacro" name="mobile_robot">
  
  <link
    name="base_link">
    <inertial>
      <origin
        xyz="0.010085 -7.8763E-06 -0.0066048"
        rpy="0 0 0" />
      <mass value="0.12" />
      <inertia
        ixx="0.0001"
        ixy="0"
        ixz="0"
        iyy="0.0003"
        iyz="0"
        izz="0.0002" />
    </inertial>
    <visual>
      <origin
        xyz="0 0 0"
        rpy="0 0 0" />
      <geometry>
        <mesh
          filename="file:///home/legacy/youtube_robot/src/modelo_robot/meshes/base_link.STL" />
      </geometry>
      <material
        name="">
        <color
          rgba="1 1 1 0.3" />
      </material>
    </visual>
    <collision>
      <origin
        xyz="0 0 0"
        rpy="0 0 0" />
      <geometry>
        <mesh
          filename="file:///home/legacy/youtube_robot/src/modelo_robot/meshes/base_link.STL" />
      </geometry>
    </collision>
  </link>

  <!--link name="world"/>
  <joint name="world_joint" type="fixed">
    <parent link="world" />
    <child link = "base_link" />
    <origin xyz="0.0 0.0 0.0" rpy="0.0 0.0 0.0" />
  </joint-->

  <gazebo reference="base_link">
    <mu1>200</mu1>
    <mu2>200</mu2>
    <kp>1000000</kp>
    <kd>1</kd>
    <material>Gazebo/White</material>
  </gazebo>

  <link
    name="Rueda_izquierda_link">
    <inertial>
      <origin
        xyz="8.9146E-10 -3.2512E-08 -0.011873"
        rpy="0 0 0" />
      <mass value="0.1403" />
      <inertia
        ixx="0.00002"
        ixy="0"
        ixz="0"
        iyy="0.00002"
        iyz="0"
        izz="0.0001" />
    </inertial>
    <visual>
      <origin
        xyz="0 0 0"
        rpy="0 0 0" />
      <geometry>
        <mesh
          filename="file:///home/legacy/youtube_robot/src/modelo_robot/meshes/Rueda_izquierda_link.STL" />
      </geometry>
      <material
        name="">
        <color
          rgba="0.79216 0.81961 0.93333 1" />
      </material>
    </visual>
    <collision>
      <origin
        xyz="0 0 0"
        rpy="0 0 0" />
      <geometry>
        <mesh
          filename="file:///home/legacy/youtube_robot/src/modelo_robot/meshes/Rueda_izquierda_link.STL" />
      </geometry>
    </collision>
  </link>
  <joint
    name="Rueda_izquierda_joint"
    type="continuous">
    <origin
      xyz="-0.033259 0.08025 -0.01375"
      rpy="-1.5708 0.042481 0" />
    <parent
      link="base_link" />
    <child
      link="Rueda_izquierda_link" />
    <axis
      xyz="0 0 1" />
    <dynamics
      damping="0.1"
      friction="0.1" />
  </joint>

 <gazebo reference="Rueda_izquierda_link">
    <mu1>200</mu1>
    <mu2>200</mu2>
    <kp>1000000</kp>
    <kd>1</kd>
    <material>Gazebo/White</material>
  </gazebo>


  <link
    name="Rueda_derecha_link">
    <inertial>
      <origin
        xyz="-8.9146E-10 -3.2512E-08 0.011873"
        rpy="0 0 0" />
      <mass value="0.1403" />
      <inertia
        ixx="0.00002"
        ixy="0"
        ixz="0"
        iyy="0.00002"
        iyz="0"
        izz="0.0001" />
    </inertial>
    <visual>
      <origin
        xyz="0 0 0"
        rpy="0 0 0" />
      <geometry>
        <mesh
          filename="file:///home/legacy/youtube_robot/src/modelo_robot/meshes/Rueda_derecha_link.STL" />
      </geometry>
      <material
        name="">
        <color
          rgba="0.79216 0.81961 0.93333 1" />
      </material>
    </visual>
    <collision>
      <origin
        xyz="0 0 0"
        rpy="0 0 0" />
      <geometry>
        <mesh
          filename="file:///home/legacy/youtube_robot/src/modelo_robot/meshes/Rueda_derecha_link.STL" />
      </geometry>
    </collision>
  </link>

  <gazebo reference="Rueda_derecha_link">
    <mu1>200</mu1>
    <mu2>200</mu2>
    <kp>1000000</kp>
    <kd>1</kd>
    <material>Gazebo/White</material>
  </gazebo>

  <joint
    name="Rueda_derecha_joint"
    type="continuous">
    <origin
      xyz="-0.033259 -0.08025 -0.01375"
      rpy="1.5708 0.042481 -3.1416" />
    <parent
      link="base_link" />
    <child
      link="Rueda_derecha_link" />
    <axis
      xyz="0 0 1" />
    <dynamics
      damping="0.1"
      friction="0.1" />
  </joint>

  <link
    name="Base_castor_link">
    <inertial>
      <origin
        xyz="0 0 0"
        rpy="0 0 0" />
      <mass
        value="0.1" />
      <inertia
        ixx="0.00004"
        ixy="0"
        ixz="0"
        iyy="0.00004"
        iyz="0"
        izz="0.00001" />
    </inertial>
    <visual>
      <origin
        xyz="0 0 0"
        rpy="0 0 0" />
      <geometry>
        <mesh
          filename="file:///home/legacy/youtube_robot/src/modelo_robot/meshes/Base_castor_link.STL" />
      </geometry>
      <material
        name="">
        <color
          rgba="1 1 1 1" />
      </material>
    </visual>
    <collision>
      <origin
        xyz="0 0 0"
        rpy="0 0 0" />
      <geometry>
        <mesh
          filename="file:///home/legacy/youtube_robot/src/modelo_robot/meshes/Base_castor_link.STL" />
      </geometry>
    </collision>
  </link>

  <gazebo reference="Base_castor_link">
    <mu1>0.1</mu1>
    <mu2>0.1</mu2>
    <kp>1000000</kp>
    <kd>1</kd>
    <material>Gazebo/White</material>
  </gazebo>

  <joint
    name="Base_castor_joint"
    type="continuous">
    <origin
      xyz="0.072581 0 -0.0025"
      rpy="-3.1408 0 0" />
    <parent
      link="base_link" />
    <child
      link="Base_castor_link" />
    <axis
      xyz="0 0 1" />
    <dynamics
      damping="0.1"
      friction="0.1" />
  </joint>
  <link
    name="Rueda_castor_link">
    <inertial>
      <origin
        xyz="6.93889390390723E-18 -2.62037475051713E-11 -2.77710070911708E-09"
        rpy="0 0 0" />
      <mass
        value="0.0828739992319076" />
      <inertia
        ixx="0.0004"
        ixy="0"
        ixz="0"
        iyy="0.0004"
        iyz="0"
        izz="0.0001" />
    </inertial>
    <visual>
      <origin
        xyz="0 0 0"
        rpy="0 0 0" />
      <geometry>
        <mesh
          filename="file:///home/legacy/youtube_robot/src/modelo_robot/meshes/Rueda_castor_link.STL" />
      </geometry>
      <material
        name="">
        <color
          rgba="1 1 1 1" />
      </material>
    </visual>
    <collision>
      <origin
        xyz="0 0 0"
        rpy="0 0 0" />
      <geometry>
        <mesh
          filename="file:///home/legacy/youtube_robot/src/modelo_robot/meshes/Rueda_castor_link.STL" />
      </geometry>
    </collision>
  </link>

  <gazebo reference="Rueda_castor_link">
    <mu1>1</mu1>
    <mu2>1</mu2>
    <kp>1000000</kp>
    <kd>1</kd>
    <material>Gazebo/White</material>
  </gazebo>

  <joint
    name="Rueda_castor_joint"
    type="continuous">
    <origin
      xyz="0.015014 -0.00012272 0.02296"
      rpy="0 -1.57 1.5708" />
    <parent
      link="Base_castor_link" />
    <child
      link="Rueda_castor_link" />
    <axis
      xyz="0 0 1" />
    <dynamics
      damping="0.1"
      friction="0.1" />
  </joint>
</robot>