<sdf version='1.7'>
  <model name='mobile_robot'>
    <link name='base_link'>
      <inertial>
        <pose>0.010085 -8e-06 -0.006605 0 -0 0</pose>
        <mass>0.12859</mass>
        <inertia>
          <ixx>5.2146e-05</ixx>
          <ixy>-1.2223e-19</ixy>
          <ixz>2.9403e-20</ixz>
          <iyy>0.00017957</iyy>
          <iyz>1.8099e-14</iyz>
          <izz>0.00022799</izz>
        </inertia>
      </inertial>
      <collision name='base_link_collision'>
        <pose>0 0 0 0 -0 0</pose>
        <geometry>
          <mesh>
            <scale>1 1 1</scale>
            <uri>base_link.STL</uri>
          </mesh>
        </geometry>
      </collision>
      <visual name='base_link_visual'>
        <pose>0 0 0 0 -0 0</pose>
        <geometry>
          <mesh>
            <scale>1 1 1</scale>
            <uri>base_link.STL</uri>
          </mesh>
        </geometry>
      </visual>
    </link>
    <joint name='Base_castor_joint' type='revolute'>
      <pose relative_to='base_link'>0.072581 0 -0.0025 -3.1408 0 0</pose>
      <parent>base_link</parent>
      <child>Base_castor_link</child>
      <axis>
        <xyz>0 0 1</xyz>
        <limit>
          <effort>100</effort>
          <velocity>100</velocity>
          <lower>-1e+16</lower>
          <upper>1e+16</upper>
        </limit>
        <dynamics>
          <damping>0.1</damping>
          <friction>0.1</friction>
          <spring_reference>0</spring_reference>
          <spring_stiffness>0</spring_stiffness>
        </dynamics>
      </axis>
    </joint>
    <link name='Base_castor_link'>
      <pose relative_to='Base_castor_joint'>0 0 0 0 -0 0</pose>
      <inertial>
        <pose>0 0 0 0 -0 0</pose>
        <mass>0.002</mass>
        <inertia>
          <ixx>0.0001</ixx>
          <ixy>0</ixy>
          <ixz>0</ixz>
          <iyy>0.0001</iyy>
          <iyz>0</iyz>
          <izz>0.0001</izz>
        </inertia>
      </inertial>
      <collision name='Base_castor_link_collision'>
        <pose>0 0 0 0 -0 0</pose>
        <geometry>
          <mesh>
            <scale>1 1 1</scale>
            <uri>model://modelo_robot/meshes/Base_castor_link.STL</uri>
          </mesh>
        </geometry>
      </collision>
      <visual name='Base_castor_link_visual'>
        <pose>0 0 0 0 -0 0</pose>
        <geometry>
          <mesh>
            <scale>1 1 1</scale>
            <uri>model://modelo_robot/meshes/Base_castor_link.STL</uri>
          </mesh>
        </geometry>
      </visual>
    </link>
    <joint name='Rueda_castor_joint' type='revolute'>
      <pose relative_to='Base_castor_link'>0.015014 -0.000123 0.02296 -0 -1.57 1.5708</pose>
      <parent>Base_castor_link</parent>
      <child>Rueda_castor_link</child>
      <axis>
        <xyz>0 0 1</xyz>
        <limit>
          <effort>100</effort>
          <velocity>100</velocity>
          <lower>-1e+16</lower>
          <upper>1e+16</upper>
        </limit>
        <dynamics>
          <damping>0.1</damping>
          <friction>0.1</friction>
          <spring_reference>0</spring_reference>
          <spring_stiffness>0</spring_stiffness>
        </dynamics>
      </axis>
    </joint>
    <link name='Rueda_castor_link'>
      <pose relative_to='Rueda_castor_joint'>0 0 0 0 -0 0</pose>
      <inertial>
        <pose>0 -0 -0 0 -0 0</pose>
        <mass>0.0082874</mass>
        <inertia>
          <ixx>6.39267e-07</ixx>
          <ixy>-7.31657e-23</ixy>
          <ixz>4.99801e-23</ixz>
          <iyy>6.393e-07</iyy>
          <iyz>3.50835e-09</iyz>
          <izz>1.01109e-06</izz>
        </inertia>
      </inertial>
      <collision name='Rueda_castor_link_collision'>
        <pose>0 0 0 0 -0 0</pose>
        <geometry>
          <mesh>
            <scale>1 1 1</scale>
            <uri>model://modelo_robot/meshes/Rueda_castor_link.STL</uri>
          </mesh>
        </geometry>
      </collision>
      <visual name='Rueda_castor_link_visual'>
        <pose>0 0 0 0 -0 0</pose>
        <geometry>
          <mesh>
            <scale>1 1 1</scale>
            <uri>model://modelo_robot/meshes/Rueda_castor_link.STL</uri>
          </mesh>
        </geometry>
      </visual>
    </link>
    <joint name='Rueda_derecha_joint' type='revolute'>
      <pose relative_to='base_link'>-0.033259 -0.08025 -0.01375 1.5708 0.042481 3.14159</pose>
      <parent>base_link</parent>
      <child>Rueda_derecha_link</child>
      <axis>
        <xyz>0 0 1</xyz>
        <limit>
          <effort>100</effort>
          <velocity>100</velocity>
          <lower>-1e+16</lower>
          <upper>1e+16</upper>
        </limit>
        <dynamics>
          <damping>0.1</damping>
          <friction>0.1</friction>
          <spring_reference>0</spring_reference>
          <spring_stiffness>0</spring_stiffness>
        </dynamics>
      </axis>
    </joint>
    <link name='Rueda_derecha_link'>
      <pose relative_to='Rueda_derecha_joint'>0 0 0 0 -0 0</pose>
      <inertial>
        <pose>-0 -0 0.011873 0 -0 0</pose>
        <mass>0.021404</mass>
        <inertia>
          <ixx>8.6283e-06</ixx>
          <ixy>6.4381e-11</ixy>
          <ixz>-1.062e-13</ixz>
          <iyy>8.6269e-06</iyy>
          <iyz>9.8999e-12</iyz>
          <izz>1.4515e-05</izz>
        </inertia>
      </inertial>
      <collision name='Rueda_derecha_link_collision'>
        <pose>0 0 0 0 -0 0</pose>
        <geometry>
          <mesh>
            <scale>1 1 1</scale>
            <uri>model://modelo_robot/meshes/Rueda_derecha_link.STL</uri>
          </mesh>
        </geometry>
      </collision>
      <visual name='Rueda_derecha_link_visual'>
        <pose>0 0 0 0 -0 0</pose>
        <geometry>
          <mesh>
            <scale>1 1 1</scale>
            <uri>model://modelo_robot/meshes/Rueda_derecha_link.STL</uri>
          </mesh>
        </geometry>
      </visual>
    </link>
    <joint name='Rueda_izquierda_joint' type='revolute'>
      <pose relative_to='base_link'>-0.033259 0.08025 -0.01375 -1.5708 0.042481 0</pose>
      <parent>base_link</parent>
      <child>Rueda_izquierda_link</child>
      <axis>
        <xyz>0 0 1</xyz>
        <limit>
          <effort>100</effort>
          <velocity>100</velocity>
          <lower>-1e+16</lower>
          <upper>1e+16</upper>
        </limit>
        <dynamics>
          <damping>0.1</damping>
          <friction>0.1</friction>
          <spring_reference>0</spring_reference>
          <spring_stiffness>0</spring_stiffness>
        </dynamics>
      </axis>
    </joint>
    <link name='Rueda_izquierda_link'>
      <pose relative_to='Rueda_izquierda_joint'>0 0 0 0 -0 0</pose>
      <inertial>
        <pose>0 -0 -0.011873 0 -0 0</pose>
        <mass>0.021404</mass>
        <inertia>
          <ixx>8.6283e-06</ixx>
          <ixy>-6.4381e-11</ixy>
          <ixz>-1.062e-13</ixz>
          <iyy>8.6269e-06</iyy>
          <iyz>-9.8999e-12</iyz>
          <izz>1.4515e-05</izz>
        </inertia>
      </inertial>
      <collision name='Rueda_izquierda_link_collision'>
        <pose>0 0 0 0 -0 0</pose>
        <geometry>
          <mesh>
            <scale>1 1 1</scale>
            <uri>model://modelo_robot/meshes/Rueda_izquierda_link.STL</uri>
          </mesh>
        </geometry>
      </collision>
      <visual name='Rueda_izquierda_link_visual'>
        <pose>0 0 0 0 -0 0</pose>
        <geometry>
          <mesh>
            <scale>1 1 1</scale>
            <uri>model://modelo_robot/meshes/Rueda_izquierda_link.STL</uri>
          </mesh>
        </geometry>
      </visual>
    </link>
  </model>
</sdf>
