<?xml version="1.0" encoding="utf-8"?>
<!-- This URDF was automatically created by SolidWorks to URDF Exporter! Originally created by Stephen Brawner (brawner@gmail.com) 
     Commit Version: 1.5.1-0-g916b5db  Build Version: 1.5.7152.31018
     For more information, please see http://wiki.ros.org/sw_urdf_exporter -->
<!--robot
  name="Seguidor_linea_robot"-->
<robot xmlns:xacro="http://www.ros.org/wiki/xacro" name="mobile_robot">
  
  <!--link name="odom_link"/>
  <joint name="odom_joint" type="fixed">
    <parent link="odom_link" />
    <child link = "base_link" />
    <origin xyz="0.0 0.0 0.0" rpy="0.0 0.0 0.0" />
  </joint-->

  <link
    name="base_link">
    <inertial>
      <origin
        xyz="0.010085 -7.8763E-06 -0.0066048"
        rpy="0 0 0" />
      <mass value="0.12" />
      <inertia
        ixx="0.0001"
        ixy="0"
        ixz="0"
        iyy="0.0003"
        iyz="0"
        izz="0.0002" />
    </inertial>
    <visual>
      <origin
        xyz="0 0 0"
        rpy="0 0 0" />
      <geometry>
        <mesh
          filename="package://modelo_robot/meshes/base_link.STL" />
      </geometry>
      <material
        name="">
        <color
          rgba="1 1 1 0.3" />
      </material>
    </visual>
    <collision>
      <origin
        xyz="0 0 0"
        rpy="0 0 0" />
      <geometry>
        <mesh
          filename="package://modelo_robot/meshes/base_link.STL" />
      </geometry>
    </collision>
  </link>

  <!--link name="world"/>
  <joint name="world_joint" type="fixed">
    <parent link="world" />
    <child link = "base_link" />
    <origin xyz="0.0 0.0 0.0" rpy="0.0 0.0 0.0" />
    package://modelo_robot/meshes/base_link.stl
  </joint-->

  <gazebo reference="base_link">
    <mu1>200</mu1>
    <mu2>200</mu2>
    <kp>1000000</kp>
    <kd>1</kd>
    <material>Gazebo/Yellow</material>
  </gazebo>

  <link
    name="Rueda_izquierda_link">
    <inertial>
      <origin
        xyz="8.9146E-10 -3.2512E-08 -0.011873"
        rpy="0 0 0" />
      <mass value="0.1403" />
      <inertia
        ixx="0.00002"
        ixy="0"
        ixz="0"
        iyy="0.00002"
        iyz="0"
        izz="0.0001" />
    </inertial>
    <visual>
      <origin
        xyz="0 0 0"
        rpy="0 0 0" />
      <geometry>
        <mesh
          filename="package://modelo_robot/meshes/Rueda_izquierda_link.STL" />
      </geometry>
      <material
        name="">
        <color
          rgba="0.79216 0.81961 0.93333 1" />
      </material>
    </visual>
    <collision>
      <origin
        xyz="0 0 0"
        rpy="0 0 0" />
      <geometry>
        <mesh
          filename="package://modelo_robot/meshes/Rueda_izquierda_link.STL" />
      </geometry>
    </collision>
  </link>
  <joint
    name="Rueda_izquierda_joint"
    type="continuous">
    <origin
      xyz="-0.033259 0.08025 -0.01375"
      rpy="-1.5708 0.042481 0" />
    <parent
      link="base_link" />
    <child
      link="Rueda_izquierda_link" />
    <axis
      xyz="0 0 1" />
    <dynamics
      damping="0.1"
      friction="0.1" />
  </joint>

 <gazebo reference="Rueda_izquierda_link">
    <mu1>200</mu1>
    <mu2>200</mu2>
    <kp>1000000</kp>
    <kd>1</kd>
    <material>Gazebo/Gray</material>
  </gazebo>


  <link
    name="Rueda_derecha_link">
    <inertial>
      <origin
        xyz="-8.9146E-10 -3.2512E-08 0.011873"
        rpy="0 0 0" />
      <mass value="0.1403" />
      <inertia
        ixx="0.00002"
        ixy="0"
        ixz="0"
        iyy="0.00002"
        iyz="0"
        izz="0.0001" />
    </inertial>
    <visual>
      <origin
        xyz="0 0 0"
        rpy="0 0 0" />
      <geometry>
        <mesh
          filename="package://modelo_robot/meshes/Rueda_derecha_link.STL" />
      </geometry>
      <material
        name="">
        <color
          rgba="0.79216 0.81961 0.93333 1" />
      </material>
    </visual>
    <collision>
      <origin
        xyz="0 0 0"
        rpy="0 0 0" />
      <geometry>
        <mesh
          filename="package://modelo_robot/meshes/Rueda_derecha_link.STL" />
      </geometry>
    </collision>
  </link>

  <gazebo reference="Rueda_derecha_link">
    <mu1>200</mu1>
    <mu2>200</mu2>
    <kp>1000000</kp>
    <kd>1</kd>
    <material>Gazebo/Gray</material>
  </gazebo>

  <joint
    name="Rueda_derecha_joint"
    type="continuous">
    <origin
      xyz="-0.033259 -0.08025 -0.01375"
      rpy="1.5708 0.042481 -3.1416" />
    <parent
      link="base_link" />
    <child
      link="Rueda_derecha_link" />
    <axis
      xyz="0 0 1" />
    <dynamics
      damping="0.1"
      friction="0.1" />
  </joint>

  <link
    name="Base_castor_link">
    <inertial>
      <origin
        xyz="0 0 0"
        rpy="0 0 0" />
      <mass
        value="0.5" />
      <inertia
        ixx="0.00004"
        ixy="0"
        ixz="0"
        iyy="0.00004"
        iyz="0"
        izz="0.00001" />
    </inertial>
    <visual>
      <origin
        xyz="0 0 0"
        rpy="0 0 0" />
      <geometry>
        <mesh
          filename="package://modelo_robot/meshes/Base_castor_link.STL" />
      </geometry>
      <material
        name="">
        <color
          rgba="1 1 1 1" />
      </material>
    </visual>
    <collision>
      <origin
        xyz="0 0 0"
        rpy="0 0 0" />
      <geometry>
        <mesh
          filename="package://modelo_robot/meshes/Base_castor_link.STL" />
      </geometry>
    </collision>
    
  </link>

  <gazebo reference="Base_castor_link">
    <mu1>0.1</mu1>
    <mu2>0.1</mu2>
    <kp>1000000</kp>
    <kd>1</kd>
    <material>Gazebo/Gray</material>
  </gazebo>

  <joint
    name="Base_castor_joint"
    type="continuous">
    <origin
      xyz="0.072581 0 -0.0025"
      rpy="-3.1408 0 0" />
    <parent
      link="base_link" />
    <child
      link="Base_castor_link" />
    <axis
      xyz="0 0 1" />
  </joint>
  <link
    name="Rueda_castor_link">
    <inertial>
      <origin
        xyz="6.93889390390723E-18 -2.62037475051713E-11 -2.77710070911708E-09"
        rpy="0 0 0" />
      <mass
        value="0.0828739992319076" />
      <inertia
        ixx="0.0004"
        ixy="0"
        ixz="0"
        iyy="0.0004"
        iyz="0"
        izz="0.00001" />
    </inertial>
    <visual>
      <origin
        xyz="0 0 0"
        rpy="0 0 0" />
      <geometry>
        <mesh
          filename="package://modelo_robot/meshes/Rueda_castor_link.STL" />
      </geometry>
      <material
        name="">
        <color
          rgba="1 1 1 1" />
      </material>
    </visual>
    <collision>
      <origin
        xyz="0 0 0"
        rpy="0 0 0" />
      <geometry>
        <mesh
          filename="package://modelo_robot/meshes/Rueda_castor_link.STL" />
      </geometry>
    </collision>
  </link>

  <gazebo reference="Rueda_castor_link">
    <mu1>0.1</mu1>
    <mu2>0.1</mu2>
    <kp>1000000</kp>
    <kd>1</kd>
    <material>Gazebo/Gray</material>
  </gazebo>

  <joint
    name="Rueda_castor_joint"
    type="continuous">
    <origin
      xyz="0.015014 -0.00012272 0.02296"
      rpy="0 -1.57 1.5708" />
    <parent
      link="Base_castor_link" />
    <child
      link="Rueda_castor_link" />
    <axis
      xyz="0 0 1" />
  </joint>

  <gazebo>
    <plugin name="two_wheeled_robot_diff_drive" filename="libgazebo_ros_diff_drive.so">
 
      <update_rate>100</update_rate>
      
      <!-- wheels -->
      <left_joint>Rueda_izquierda_joint</left_joint>
      <right_joint>Rueda_derecha_joint</right_joint>
 
      <!-- kinematics -->
      <wheel_separation>0.15</wheel_separation>
      <wheel_diameter>0.06</wheel_diameter>
 
      <!-- limits -->
      <max_wheel_torque>20</max_wheel_torque>
      <max_wheel_acceleration>20.0</max_wheel_acceleration>
 
      <!-- Receive velocity commands on this ROS topic -->
      <command_topic>cmd_vel</command_topic>
 
      <!-- output -->
      <!-- When false, publish no wheel odometry data to a ROS topic -->
      <publish_odom>true</publish_odom>
 
      <!-- When true, publish coordinate transform from odom to base_footprint -->
      <!-- I usually use the robot_localization package to publish this transform -->  
      <publish_odom_tf>true</publish_odom_tf>
     
      <!-- When true, publish coordinate transform from base_link to the wheels -->
      <!-- The robot_state_publisher package is often used to publish this transform -->  
      <publish_wheel_tf>true</publish_wheel_tf>
 
      <odometry_topic>odom</odometry_topic>
      <odometry_frame>odom_link</odometry_frame>
      <robot_base_frame>base_link</robot_base_frame>
 
      <odometry_source>1</odometry_source>
      <ros>
        <remapping>odom:=wheel/odometry</remapping>
      </ros>
    </plugin>
  </gazebo>

  <gazebo>
    <plugin name="gazebo_ros_joint_state_publisher"
        filename="libgazebo_ros_joint_state_publisher.so">
        <update_rate>100</update_rate>
        <joint_name>Base_castor_joint</joint_name>
        <joint_name>Rueda_castor_joint</joint_name>
    </plugin>
  </gazebo>

</robot>
